Workbook

Sheet Instructions
B2: Household Budget Tool
B3: A weekly-tracking, monthly-rollup budget workbook
B5: How this workbook is organized
B6: Income | C6: Enter each income source and its expected amount per month.
B7: BudgetCategories | C7: Set your monthly budget target for each spending category.
B8: FortnightlyLog | C8: Log every transaction here as you spend, each fortnight.
B9: MonthlySummary | C9: Automatically rolls up the weekly log into a month-by-month view vs. your budget.
B10: Dashboard | C10: At-a-glance KPIs and charts. Nothing to edit here.
B12: Color legend
B13: Blue text | C13: A cell you type into (inputs)
B14: Black text | C14: A formula — don't overwrite
B15: Yellow fill | C15: Key assumption or setting to review
B16: Green text | C16: A link pulling data from another sheet
B18: Getting started
B19: 1. Go to Income and enter your monthly income sources (blue cells).
B20: 2. Go to BudgetCategories and set a monthly budget for each category (blue cells).
B21: 3. Each fortnight, add rows to FortnightlyLog: date, category (pick from dropdown), description, amount.
B22: 4. Check MonthlySummary and Dashboard any time to see how you're tracking against budget.

Sheet Income
B2: Monthly Income
B3: Enter expected income by source for each month (blue cells).
B5: Income Source | C5: Jan | D5: Feb | E5: Mar | F5: Apr | G5: May | H5: Jun | I5: Jul | J5: Aug | K5: Sep | L5: Oct | M5: Nov | N5: Dec | O5: Annual Total
B6: Primary Salary | C6: 3752 | D6: 3752 | E6: 3752 | F6: 3752 | G6: 3752 | H6: 3752 | I6: 3762 | J6: 3787 | K6: 3787 | L6: 0 | M6: 0 | N6: 0 | O6: =SUM(C6:N6) -> 33848
B7: Primary Salary - 2 | C7: 3752 | D7: 3752 | E7: 3752 | F7: 6316 | G7: 2052 | H7: 3752 | I7: 3787 | J7: 3787 | K7: 0 | L7: 0 | M7: 0 | N7: 0 | O7: =SUM(C7:N7) -> 30950
B8: Primary Salary - 3 | C8: 0 | D8: 0 | E8: 0 | F8: 0 | G8: 0 | H8: 0 | I8: 3787 | J8: 0 | K8: 0 | L8: 0 | M8: 0 | N8: 0 | O8: =SUM(C8:N8) -> 3787
B9: Secondary Salary | C9: 0 | D9: 0 | E9: 0 | F9: 0 | G9: 0 | H9: 0 | I9: 0 | J9: 0 | K9: 0 | L9: 0 | M9: 0 | N9: 0 | O9: =SUM(C9:N9) -> 0
B10: Side Income | C10: 0 | D10: 0 | E10: 0 | F10: 0 | G10: 0 | H10: 0 | I10: 0 | J10: 0 | K10: 0 | L10: 0 | M10: 0 | N10: 0 | O10: =SUM(C10:N10) -> 0
B11: Other Income | C11: 0 | D11: 143 | E11: 0 | F11: 0 | G11: 0 | H11: 0 | I11: 120 | J11: 0 | K11: 0 | L11: 0 | M11: 0 | N11: 0 | O11: =SUM(C11:N11) -> 263
B12: Total Income | C12: =SUM(C6:C11) -> 7504 | D12: =SUM(D6:D11) -> 7647 | E12: =SUM(E6:E11) -> 7504 | F12: =SUM(F6:F11) -> 10068 | G12: =SUM(G6:G11) -> 5804 | H12: =SUM(H6:H11) -> 7504 | I12: =SUM(I7:I11) -> 7694 | J12: =SUM(J6:J11) -> 7574 | K12: =SUM(K6:K11) -> 3787 | L12: =SUM(L6:L11) -> 0 | M12: =SUM(M6:M11) -> 0 | N12: =SUM(N6:N11) -> 0 | O12: =SUM(O6:O11) -> 68848

Sheet BudgetCategories
B2: Budget Categories
B3: Set a monthly budget target per category (blue cells). Annual budget calculates automatically.
B5: Category | C5: Type | D5: Monthly Budget | E5: Annual Budget
B6: Rent | C6: Fixed
B7: Utilities | C7: Variable
B8: Groceries | C8: Variable
B9: Transportation | C9: Variable
B10: Insurance | C10: Fixed
B11: Dining Out | C11: Variable
B12: Entertainment | C12: Variable
B13: Health & Fitness | C13: Variable
B14: Personal Care | C14: Variable
B15: Subscriptions | C15: Fixed
B16: Miscellaneous | C16: Variable
B17: Total | D17: =SUM(D6:D16) -> 0 | E17: =SUM(E6:E16) -> 0

Sheet FortnightlyLog
B2: Fortnightly Expense Log
B3: Add one row per transaction. Date, Category and Amount are the only cells you fill in (blue).
B5: Date | C5: Fortnight # | D5: Month | E5: Category | F5: Description | G5: Amount
B6: 46024 | C6: =IF(B6="","",INT((B6-DATE(YEAR(B6),1,1))/14)+1) -> 1 | D6: =IF(B6="","",TEXT(B6,"mmm")) -> Jan | E6: Dining Out | F6: Dominos | G6: 7.09
B7: 46024 | C7: =IF(B7="","",INT((B7-DATE(YEAR(B7),1,1))/14)+1) -> 1 | D7: =IF(B7="","",TEXT(B7,"mmm")) -> Jan | E7: Dining Out | F7: Nandos | G7: 17.95
B8: 46024 | C8: =IF(B8="","",INT((B8-DATE(YEAR(B8),1,1))/14)+1) -> 1 | D8: =IF(B8="","",TEXT(B8,"mmm")) -> Jan | E8: Dining Out | F8: Nene Chicken | G8: 32.85
B9: 46024 | C9: =IF(B9="","",INT((B9-DATE(YEAR(B9),1,1))/14)+1) -> 1 | D9: =IF(B9="","",TEXT(B9,"mmm")) -> Jan | E9: Groceries | F9: Aldi | G9: 83.76
B10: 46027 | C10: =IF(B10="","",INT((B10-DATE(YEAR(B10),1,1))/14)+1) -> 1 | D10: =IF(B10="","",TEXT(B10,"mmm")) -> Jan | E10: Dining Out | F10: Swan Valley | G10: 30.48
B11: 46027 | C11: =IF(B11="","",INT((B11-DATE(YEAR(B11),1,1))/14)+1) -> 1 | D11: =IF(B11="","",TEXT(B11,"mmm")) -> Jan | E11: Groceries | F11: SpudShed | G11: 77.86
B12: 46027 | C12: =IF(B12="","",INT((B12-DATE(YEAR(B12),1,1))/14)+1) -> 1 | D12: =IF(B12="","",TEXT(B12,"mmm")) -> Jan | E12: Miscellaneous | F12: Flight Ticket | G12: 446.79
B13: 46027 | C13: =IF(B13="","",INT((B13-DATE(YEAR(B13),1,1))/14)+1) -> 1 | D13: =IF(B13="","",TEXT(B13,"mmm")) -> Jan | E13: Transportation | F13: Transperth | G13: 20
B14: 46029 | C14: =IF(B14="","",INT((B14-DATE(YEAR(B14),1,1))/14)+1) -> 1 | D14: =IF(B14="","",TEXT(B14,"mmm")) -> Jan | E14: Groceries | F14: Shopping | G14: 101
B15: 46029 | C15: =IF(B15="","",INT((B15-DATE(YEAR(B15),1,1))/14)+1) -> 1 | D15: =IF(B15="","",TEXT(B15,"mmm")) -> Jan | E15: Rent | F15: Rent | G15: 480
B16: 46029 | C16: =IF(B16="","",INT((B16-DATE(YEAR(B16),1,1))/14)+1) -> 1 | D16: =IF(B16="","",TEXT(B16,"mmm")) -> Jan | E16: Utilities | F16: Internet | G16: 74
B17: 46030 | C17: =IF(B17="","",INT((B17-DATE(YEAR(B17),1,1))/14)+1) -> 1 | D17: =IF(B17="","",TEXT(B17,"mmm")) -> Jan | E17: Insurance | F17: Car | G17: 28.64
... B25: 46036 | C25: =IF(B25="","",INT((B25-DATE(YEAR(B25),1,1))/14)+1) -> 1 | D25: =IF(B25="","",TEXT(B25,"mmm")) -> Jan | E25: Utilities | F25: Mobile | G25: 39
B26: 46037 | C26: 1 | D26: =IF(B26="","",TEXT(B26,"mmm")) -> Jan | E26: Miscellaneous | F26: Miscellaneous | G26: 226
B27: 46038 | C27: =IF(B27="","",INT((B27-DATE(YEAR(B27),1,1))/14)+1) -> 2 | D27: =IF(B27="","",TEXT(B27,"mmm")) -> Jan | E27: Transportation | F27: Transperth | G27: 20
B28: 46041 | C28: =IF(B28="","",INT((B28-DATE(YEAR(B28),1,1))/14)+1) -> 2 | D28: =IF(B28="","",TEXT(B28,"mmm")) -> Jan | E28: Subscriptions | F28: Netflix | G28: 9.99
B29: 46041 | C29: =IF(B29="","",INT((B29-DATE(YEAR(B29),1,1))/14)+1) -> 2 | D29: =IF(B29="","",TEXT(B29,"mmm")) -> Jan | E29: Miscellaneous | F29: BigW | G29: 12
B30: 46041 | C30: =IF(B30="","",INT((B30-DATE(YEAR(B30),1,1))/14)+1) -> 2 | D30: =IF(B30="","",TEXT(B30,"mmm")) -> Jan | E30: Groceries | F30: spudshed | G30: 12.46
B31: 46041 | C31: =IF(B31="","",INT((B31-DATE(YEAR(B31),1,1))/14)+1) -> 2 | D31: =IF(B31="","",TEXT(B31,"mmm")) -> Jan | E31: Miscellaneous | F31: Barber | G31: 25.39
B32: 46041 | C32: =IF(B32="","",INT((B32-DATE(YEAR(B32),1,1))/14)+1) -> 2 | D32: =IF(B32="","",TEXT(B32,"mmm")) -> Jan | E32: Miscellaneous | F32: Miscellaneous | G32: 42
B33: 46041 | C33: =IF(B33="","",INT((B33-DATE(YEAR(B33),1,1))/14)+1) -> 2 | D33: =IF(B33="","",TEXT(B33,"mmm")) -> Jan | E33: Transportation | F33: BP | G33: 33.51
B34: 46041 | C34: =IF(B34="","",INT((B34-DATE(YEAR(B34),1,1))/14)+1) -> 2 | D34: =IF(B34="","",TEXT(B34,"mmm")) -> Jan | E34: Groceries | F34: Aldi | G34: 30.91
B35: 46041 | C35: =IF(B35="","",INT((B35-DATE(YEAR(B35),1,1))/14)+1) -> 2 | D35: =IF(B35="","",TEXT(B35,"mmm")) -> Jan | E35: Miscellaneous | F35: Karrinyup | G35: 4.97
B36: 46043 | C36: =IF(B36="","",INT((B36-DATE(YEAR(B36),1,1))/14)+1) -> 2 | D36: =IF(B36="","",TEXT(B36,"mmm")) -> Jan | E36: Groceries | F36: K-mart | G36: 2
B37: 46043 | C37: =IF(B37="","",INT((B37-DATE(YEAR(B37),1,1))/14)+1) -> 2 | D37: =IF(B37="","",TEXT(B37,"mmm")) -> Jan | E37: Groceries | F37: SeaFresh | G37: 11.26
B38: 46043 | C38: =IF(B38="","",INT((B38-DATE(YEAR(B38),1,1))/14)+1) -> 2 | D38: =IF(B38="","",TEXT(B38,"mmm")) -> Jan | E38: Groceries | F38: SeaFresh | G38: 26.33
... B53: 46050 | C53: =IF(B53="","",INT((B53-DATE(YEAR(B53),1,1))/14)+1) -> 2 | D53: =IF(B53="","",TEXT(B53,"mmm")) -> Jan | E53: Rent | F53: Rent | G53: 500
B54: 46051 | C54: 2 | D54: =IF(B54="","",TEXT(B54,"mmm")) -> Jan | E54: Dining Out | F54: Nene Chicken | G54: 42.54
B55: 46051 | C55: 2 | D55: =IF(B55="","",TEXT(B55,"mmm")) -> Jan | E55: Groceries | F55: SeaFresh | G55: 36.37
B56: 46051 | C56: 2 | D56: =IF(B56="","",TEXT(B56,"mmm")) -> Jan | E56: Groceries | F56: K-mart | G56: 29.5
B57: 46052 | C57: 2 | D57: =IF(B57="","",TEXT(B57,"mmm")) -> Jan | E57: Groceries | F57: Aldi | G57: 14.24
B58: 46052 | C58: 2 | D58: =IF(B58="","",TEXT(B58,"mmm")) -> Jan | E58: Dining Out | F58: Golden Bakery | G58: 23.9
B59: 46055 | C59: 1 | D59: =IF(B59="","",TEXT(B59,"mmm")) -> Feb | E59: Personal Care | F59: Chemist Warehouse | G59: 16.99
B60: 46055 | C60: 1 | D60: =IF(B60="","",TEXT(B60,"mmm")) -> Feb | E60: Miscellaneous | F60: Karrinyup | G60: 20.9
B61: 46055 | C61: 1 | D61: =IF(B61="","",TEXT(B61,"mmm")) -> Feb | E61: Miscellaneous | F61: Myer | G61: 203.96
B62: 46055 | C62: 1 | D62: =IF(B62="","",TEXT(B62,"mmm")) -> Feb | E62: Dining Out | F62: Crown Perth | G62: 239.8
B63: 46055 | C63: 1 | D63: =IF(B63="","",TEXT(B63,"mmm")) -> Feb | E63: Insurance | F63: Car | G63: 274.96
...

Sheet MonthlySummary
B2: Monthly Summary — Budget
B3: Automatically calculated from FortnightlyLog. Nothing to edit on this sheet.
B5: Category | C5: Jan | D5: Feb | E5: Mar | F5: Apr | G5: May | H5: Jun | I5: Jul | J5: Aug | K5: Sep | L5: Oct | M5: Nov | N5: Dec | O5: Actual Total
B6: =BudgetCategories!B6 -> Rent | C6: =SUMIFS(FortnightlyLog!$G$6:$G$300,FortnightlyLog!$E$6:$E$300,$B6,FortnightlyLog!$D$6:$D$300,C$5) -> 1960 | D6: =SUMIFS(FortnightlyLog!$G$6:$G$300,FortnightlyLog!$E$6:$E$300,$B6,FortnightlyLog!$D$6:$D$300,D$5) -> 1000 | E6: =SUMIFS(FortnightlyLog!$G$6:$G$300,FortnightlyLog!$E$6:$E$300,$B6,FortnightlyLog!$D$6:$D$300,E$5) -> 0 | F6: =SUMIFS(FortnightlyLog!$G$6:$G$300,FortnightlyLog!$E$6:$E$300,$B6,FortnightlyLog!$D$6:$D$300,F$5) -> 0 | G6: =SUMIFS(FortnightlyLog!$G$6:$G$300,FortnightlyLog!$E$6:$E$300,$B6,FortnightlyLog!$D$6:$D$300,G$5) -> 0 | H6: =SUMIFS(FortnightlyLog!$G$6:$G$300,FortnightlyLog!$E$6:$E$300,$B6,FortnightlyLog!$D$6:$D$300,H$5) -> 0 | I6: =SUMIFS(FortnightlyLog!$G$6:$G$300,FortnightlyLog!$E$6:$E$300,$B6,FortnightlyLog!$D$6:$D$300,I$5) -> 0 | J6: =SUMIFS(FortnightlyLog!$G$6:$G$300,FortnightlyLog!$E$6:$E$300,$B6,FortnightlyLog!$D$6:$D$300,J$5) -> 0 | ... N6: =SUMIFS(FortnightlyLog!$G$6:$G$300,FortnightlyLog!$E$6:$E$300,$B6,FortnightlyLog!$D$6:$D$300,N$5) -> 0 | O6: =SUM(C6:N6) -> 2960
B7: =BudgetCategories!B7 -> Utilities | C7: =SUMIFS(FortnightlyLog!$G$6:$G$300,FortnightlyLog!$E$6:$E$300,$B7,FortnightlyLog!$D$6:$D$300,C$5) -> 269.5 | D7: =SUMIFS(FortnightlyLog!$G$6:$G$300,FortnightlyLog!$E$6:$E$300,$B7,FortnightlyLog!$D$6:$D$300,D$5) -> 59 | E7: =SUMIFS(FortnightlyLog!$G$6:$G$300,FortnightlyLog!$E$6:$E$300,$B7,FortnightlyLog!$D$6:$D$300,E$5) -> 0 | F7: =SUMIFS(FortnightlyLog!$G$6:$G$300,FortnightlyLog!$E$6:$E$300,$B7,FortnightlyLog!$D$6:$D$300,F$5) -> 0 | G7: =SUMIFS(FortnightlyLog!$G$6:$G$300,FortnightlyLog!$E$6:$E$300,$B7,FortnightlyLog!$D$6:$D$300,G$5) -> 0 | H7: =SUMIFS(FortnightlyLog!$G$6:$G$300,FortnightlyLog!$E$6:$E$300,$B7,FortnightlyLog!$D$6:$D$300,H$5) -> 0 | I7: =SUMIFS(FortnightlyLog!$G$6:$G$300,FortnightlyLog!$E$6:$E$300,$B7,FortnightlyLog!$D$6:$D$300,I$5) -> 0 | J7: =SUMIFS(FortnightlyLog!$G$6:$G$300,FortnightlyLog!$E$6:$E$300,$B7,FortnightlyLog!$D$6:$D$300,J$5) -> 0 | ... N7: =SUMIFS(FortnightlyLog!$G$6:$G$300,FortnightlyLog!$E$6:$E$300,$B7,FortnightlyLog!$D$6:$D$300,N$5) -> 0 | O7: =SUM(C7:N7) -> 328.5
B8: =BudgetCategories!B8 -> Groceries | C8: =SUMIFS(FortnightlyLog!$G$6:$G$300,FortnightlyLog!$E$6:$E$300,$B8,FortnightlyLog!$D$6:$D$300,C$5) -> 650.86 | D8: =SUMIFS(FortnightlyLog!$G$6:$G$300,FortnightlyLog!$E$6:$E$300,$B8,FortnightlyLog!$D$6:$D$300,D$5) -> 98.49 | E8: =SUMIFS(FortnightlyLog!$G$6:$G$300,FortnightlyLog!$E$6:$E$300,$B8,FortnightlyLog!$D$6:$D$300,E$5) -> 0 | F8: =SUMIFS(FortnightlyLog!$G$6:$G$300,FortnightlyLog!$E$6:$E$300,$B8,FortnightlyLog!$D$6:$D$300,F$5) -> 0 | G8: =SUMIFS(FortnightlyLog!$G$6:$G$300,FortnightlyLog!$E$6:$E$300,$B8,FortnightlyLog!$D$6:$D$300,G$5) -> 0 | H8: =SUMIFS(FortnightlyLog!$G$6:$G$300,FortnightlyLog!$E$6:$E$300,$B8,FortnightlyLog!$D$6:$D$300,H$5) -> 0 | I8: =SUMIFS(FortnightlyLog!$G$6:$G$300,FortnightlyLog!$E$6:$E$300,$B8,FortnightlyLog!$D$6:$D$300,I$5) -> 0 | J8: =SUMIFS(FortnightlyLog!$G$6:$G$300,FortnightlyLog!$E$6:$E$300,$B8,FortnightlyLog!$D$6:$D$300,J$5) -> 0 | ... N8: =SUMIFS(FortnightlyLog!$G$6:$G$300,FortnightlyLog!$E$6:$E$300,$B8,FortnightlyLog!$D$6:$D$300,N$5) -> 0 | O8: =SUM(C8:N8) -> 749.35
B9: =BudgetCategories!B9 -> Transportation | C9: =SUMIFS(FortnightlyLog!$G$6:$G$300,FortnightlyLog!$E$6:$E$300,$B9,FortnightlyLog!$D$6:$D$300,C$5) -> 133.51 | D9: =SUMIFS(FortnightlyLog!$G$6:$G$300,FortnightlyLog!$E$6:$E$300,$B9,FortnightlyLog!$D$6:$D$300,D$5) -> 192.45 | E9: =SUMIFS(FortnightlyLog!$G$6:$G$300,FortnightlyLog!$E$6:$E$300,$B9,FortnightlyLog!$D$6:$D$300,E$5) -> 0 | F9: =SUMIFS(FortnightlyLog!$G$6:$G$300,FortnightlyLog!$E$6:$E$300,$B9,FortnightlyLog!$D$6:$D$300,F$5) -> 0 | G9: =SUMIFS(FortnightlyLog!$G$6:$G$300,FortnightlyLog!$E$6:$E$300,$B9,FortnightlyLog!$D$6:$D$300,G$5) -> 0 | H9: =SUMIFS(FortnightlyLog!$G$6:$G$300,FortnightlyLog!$E$6:$E$300,$B9,FortnightlyLog!$D$6:$D$300,H$5) -> 0 | I9: =SUMIFS(FortnightlyLog!$G$6:$G$300,FortnightlyLog!$E$6:$E$300,$B9,FortnightlyLog!$D$6:$D$300,I$5) -> 0 | J9: =SUMIFS(FortnightlyLog!$G$6:$G$300,FortnightlyLog!$E$6:$E$300,$B9,FortnightlyLog!$D$6:$D$300,J$5) -> 0 | ... N9: =SUMIFS(FortnightlyLog!$G$6:$G$300,FortnightlyLog!$E$6:$E$300,$B9,FortnightlyLog!$D$6:$D$300,N$5) -> 0 | O9: =SUM(C9:N9) -> 325.96
B10: =BudgetCategories!B10 -> Insurance | C10: =SUMIFS(FortnightlyLog!$G$6:$G$300,FortnightlyLog!$E$6:$E$300,$B10,FortnightlyLog!$D$6:$D$300,C$5) -> 143.38 | D10: =SUMIFS(FortnightlyLog!$G$6:$G$300,FortnightlyLog!$E$6:$E$300,$B10,FortnightlyLog!$D$6:$D$300,D$5) -> 274.96 | E10: =SUMIFS(FortnightlyLog!$G$6:$G$300,FortnightlyLog!$E$6:$E$300,$B10,FortnightlyLog!$D$6:$D$300,E$5) -> 0 | F10: =SUMIFS(FortnightlyLog!$G$6:$G$300,FortnightlyLog!$E$6:$E$300,$B10,FortnightlyLog!$D$6:$D$300,F$5) -> 0 | G10: =SUMIFS(FortnightlyLog!$G$6:$G$300,FortnightlyLog!$E$6:$E$300,$B10,FortnightlyLog!$D$6:$D$300,G$5) -> 0 | H10: =SUMIFS(FortnightlyLog!$G$6:$G$300,FortnightlyLog!$E$6:$E$300,$B10,FortnightlyLog!$D$6:$D$300,H$5) -> 0 | I10: =SUMIFS(FortnightlyLog!$G$6:$G$300,FortnightlyLog!$E$6:$E$300,$B10,FortnightlyLog!$D$6:$D$300,I$5) -> 0 | J10: =SUMIFS(FortnightlyLog!$G$6:$G$300,FortnightlyLog!$E$6:$E$300,$B10,FortnightlyLog!$D$6:$D$300,J$5) -> 0 | ... N10: =SUMIFS(FortnightlyLog!$G$6:$G$300,FortnightlyLog!$E$6:$E$300,$B10,FortnightlyLog!$D$6:$D$300,N$5) -> 0 | O10: =SUM(C10:N10) -> 418.34
B11: =BudgetCategories!B11 -> Dining Out | C11: =SUMIFS(FortnightlyLog!$G$6:$G$300,FortnightlyLog!$E$6:$E$300,$B11,FortnightlyLog!$D$6:$D$300,C$5) -> 258.77 | D11: =SUMIFS(FortnightlyLog!$G$6:$G$300,FortnightlyLog!$E$6:$E$300,$B11,FortnightlyLog!$D$6:$D$300,D$5) -> 446.67 | E11: =SUMIFS(FortnightlyLog!$G$6:$G$300,FortnightlyLog!$E$6:$E$300,$B11,FortnightlyLog!$D$6:$D$300,E$5) -> 0 | F11: =SUMIFS(FortnightlyLog!$G$6:$G$300,FortnightlyLog!$E$6:$E$300,$B11,FortnightlyLog!$D$6:$D$300,F$5) -> 0 | G11: =SUMIFS(FortnightlyLog!$G$6:$G$300,FortnightlyLog!$E$6:$E$300,$B11,FortnightlyLog!$D$6:$D$300,G$5) -> 0 | H11: =SUMIFS(FortnightlyLog!$G$6:$G$300,FortnightlyLog!$E$6:$E$300,$B11,FortnightlyLog!$D$6:$D$300,H$5) -> 0 | I11: =SUMIFS(FortnightlyLog!$G$6:$G$300,FortnightlyLog!$E$6:$E$300,$B11,FortnightlyLog!$D$6:$D$300,I$5) -> 0 | J11: =SUMIFS(FortnightlyLog!$G$6:$G$300,FortnightlyLog!$E$6:$E$300,$B11,FortnightlyLog!$D$6:$D$300,J$5) -> 0 | ... N11: =SUMIFS(FortnightlyLog!$G$6:$G$300,FortnightlyLog!$E$6:$E$300,$B11,FortnightlyLog!$D$6:$D$300,N$5) -> 0 | O11: =SUM(C11:N11) -> 705.44
B12: =BudgetCategories!B12 -> Entertainment | C12: =SUMIFS(FortnightlyLog!$G$6:$G$300,FortnightlyLog!$E$6:$E$300,$B12,FortnightlyLog!$D$6:$D$300,C$5) -> 0 | D12: =SUMIFS(FortnightlyLog!$G$6:$G$300,FortnightlyLog!$E$6:$E$300,$B12,FortnightlyLog!$D$6:$D$300,D$5) -> 0 | E12: =SUMIFS(FortnightlyLog!$G$6:$G$300,FortnightlyLog!$E$6:$E$300,$B12,FortnightlyLog!$D$6:$D$300,E$5) -> 0 | F12: =SUMIFS(FortnightlyLog!$G$6:$G$300,FortnightlyLog!$E$6:$E$300,$B12,FortnightlyLog!$D$6:$D$300,F$5) -> 0 | G12: =SUMIFS(FortnightlyLog!$G$6:$G$300,FortnightlyLog!$E$6:$E$300,$B12,FortnightlyLog!$D$6:$D$300,G$5) -> 0 | H12: =SUMIFS(FortnightlyLog!$G$6:$G$300,FortnightlyLog!$E$6:$E$300,$B12,FortnightlyLog!$D$6:$D$300,H$5) -> 0 | I12: =SUMIFS(FortnightlyLog!$G$6:$G$300,FortnightlyLog!$E$6:$E$300,$B12,FortnightlyLog!$D$6:$D$300,I$5) -> 0 | J12: =SUMIFS(FortnightlyLog!$G$6:$G$300,FortnightlyLog!$E$6:$E$300,$B12,FortnightlyLog!$D$6:$D$300,J$5) -> 0 | ... N12: =SUMIFS(FortnightlyLog!$G$6:$G$300,FortnightlyLog!$E$6:$E$300,$B12,FortnightlyLog!$D$6:$D$300,N$5) -> 0 | O12: =SUM(C12:N12) -> 0
B13: =BudgetCategories!B13 -> Health & Fitness | C13: =SUMIFS(FortnightlyLog!$G$6:$G$300,FortnightlyLog!$E$6:$E$300,$B13,FortnightlyLog!$D$6:$D$300,C$5) -> 0 | D13: =SUMIFS(FortnightlyLog!$G$6:$G$300,FortnightlyLog!$E$6:$E$300,$B13,FortnightlyLog!$D$6:$D$300,D$5) -> 0 | E13: =SUMIFS(FortnightlyLog!$G$6:$G$300,FortnightlyLog!$E$6:$E$300,$B13,FortnightlyLog!$D$6:$D$300,E$5) -> 0 | F13: =SUMIFS(FortnightlyLog!$G$6:$G$300,FortnightlyLog!$E$6:$E$300,$B13,FortnightlyLog!$D$6:$D$300,F$5) -> 0 | G13: =SUMIFS(FortnightlyLog!$G$6:$G$300,FortnightlyLog!$E$6:$E$300,$B13,FortnightlyLog!$D$6:$D$300,G$5) -> 0 | H13: =SUMIFS(FortnightlyLog!$G$6:$G$300,FortnightlyLog!$E$6:$E$300,$B13,FortnightlyLog!$D$6:$D$300,H$5) -> 0 | I13: =SUMIFS(FortnightlyLog!$G$6:$G$300,FortnightlyLog!$E$6:$E$300,$B13,FortnightlyLog!$D$6:$D$300,I$5) -> 0 | J13: =SUMIFS(FortnightlyLog!$G$6:$G$300,FortnightlyLog!$E$6:$E$300,$B13,FortnightlyLog!$D$6:$D$300,J$5) -> 0 | ... N13: =SUMIFS(FortnightlyLog!$G$6:$G$300,FortnightlyLog!$E$6:$E$300,$B13,FortnightlyLog!$D$6:$D$300,N$5) -> 0 | O13: =SUM(C13:N13) -> 0
B14: =BudgetCategories!B14 -> Personal Care | C14: =SUMIFS(FortnightlyLog!$G$6:$G$300,FortnightlyLog!$E$6:$E$300,$B14,FortnightlyLog!$D$6:$D$300,C$5) -> 30.97 | D14: =SUMIFS(FortnightlyLog!$G$6:$G$300,FortnightlyLog!$E$6:$E$300,$B14,FortnightlyLog!$D$6:$D$300,D$5) -> 16.99 | E14: =SUMIFS(FortnightlyLog!$G$6:$G$300,FortnightlyLog!$E$6:$E$300,$B14,FortnightlyLog!$D$6:$D$300,E$5) -> 0 | F14: =SUMIFS(FortnightlyLog!$G$6:$G$300,FortnightlyLog!$E$6:$E$300,$B14,FortnightlyLog!$D$6:$D$300,F$5) -> 0 | G14: =SUMIFS(FortnightlyLog!$G$6:$G$300,FortnightlyLog!$E$6:$E$300,$B14,FortnightlyLog!$D$6:$D$300,G$5) -> 0 | H14: =SUMIFS(FortnightlyLog!$G$6:$G$300,FortnightlyLog!$E$6:$E$300,$B14,FortnightlyLog!$D$6:$D$300,H$5) -> 0 | I14: =SUMIFS(FortnightlyLog!$G$6:$G$300,FortnightlyLog!$E$6:$E$300,$B14,FortnightlyLog!$D$6:$D$300,I$5) -> 0 | J14: =SUMIFS(FortnightlyLog!$G$6:$G$300,FortnightlyLog!$E$6:$E$300,$B14,FortnightlyLog!$D$6:$D$300,J$5) -> 0 | ... N14: =SUMIFS(FortnightlyLog!$G$6:$G$300,FortnightlyLog!$E$6:$E$300,$B14,FortnightlyLog!$D$6:$D$300,N$5) -> 0 | O14: =SUM(C14:N14) -> 47.96
B15: =BudgetCategories!B15 -> Subscriptions | C15: =SUMIFS(FortnightlyLog!$G$6:$G$300,FortnightlyLog!$E$6:$E$300,$B15,FortnightlyLog!$D$6:$D$300,C$5) -> 9.99 | D15: =SUMIFS(FortnightlyLog!$G$6:$G$300,FortnightlyLog!$E$6:$E$300,$B15,FortnightlyLog!$D$6:$D$300,D$5) -> 0 | E15: =SUMIFS(FortnightlyLog!$G$6:$G$300,FortnightlyLog!$E$6:$E$300,$B15,FortnightlyLog!$D$6:$D$300,E$5) -> 0 | F15: =SUMIFS(FortnightlyLog!$G$6:$G$300,FortnightlyLog!$E$6:$E$300,$B15,FortnightlyLog!$D$6:$D$300,F$5) -> 0 | G15: =SUMIFS(FortnightlyLog!$G$6:$G$300,FortnightlyLog!$E$6:$E$300,$B15,FortnightlyLog!$D$6:$D$300,G$5) -> 0 | H15: =SUMIFS(FortnightlyLog!$G$6:$G$300,FortnightlyLog!$E$6:$E$300,$B15,FortnightlyLog!$D$6:$D$300,H$5) -> 0 | I15: =SUMIFS(FortnightlyLog!$G$6:$G$300,FortnightlyLog!$E$6:$E$300,$B15,FortnightlyLog!$D$6:$D$300,I$5) -> 0 | J15: =SUMIFS(FortnightlyLog!$G$6:$G$300,FortnightlyLog!$E$6:$E$300,$B15,FortnightlyLog!$D$6:$D$300,J$5) -> 0 | ... N15: =SUMIFS(FortnightlyLog!$G$6:$G$300,FortnightlyLog!$E$6:$E$300,$B15,FortnightlyLog!$D$6:$D$300,N$5) -> 0 | O15: =SUM(C15:N15) -> 9.99
B16: =BudgetCategories!B16 -> Miscellaneous | C16: =SUMIFS(FortnightlyLog!$G$6:$G$300,FortnightlyLog!$E$6:$E$300,$B16,FortnightlyLog!$D$6:$D$300,C$5) -> 1279.15 | D16: =SUMIFS(FortnightlyLog!$G$6:$G$300,FortnightlyLog!$E$6:$E$300,$B16,FortnightlyLog!$D$6:$D$300,D$5) -> 263.65 | E16: =SUMIFS(FortnightlyLog!$G$6:$G$300,FortnightlyLog!$E$6:$E$300,$B16,FortnightlyLog!$D$6:$D$300,E$5) -> 0 | F16: =SUMIFS(FortnightlyLog!$G$6:$G$300,FortnightlyLog!$E$6:$E$300,$B16,FortnightlyLog!$D$6:$D$300,F$5) -> 0 | G16: =SUMIFS(FortnightlyLog!$G$6:$G$300,FortnightlyLog!$E$6:$E$300,$B16,FortnightlyLog!$D$6:$D$300,G$5) -> 0 | H16: =SUMIFS(FortnightlyLog!$G$6:$G$300,FortnightlyLog!$E$6:$E$300,$B16,FortnightlyLog!$D$6:$D$300,H$5) -> 0 | I16: =SUMIFS(FortnightlyLog!$G$6:$G$300,FortnightlyLog!$E$6:$E$300,$B16,FortnightlyLog!$D$6:$D$300,I$5) -> 0 | J16: =SUMIFS(FortnightlyLog!$G$6:$G$300,FortnightlyLog!$E$6:$E$300,$B16,FortnightlyLog!$D$6:$D$300,J$5) -> 0 | ... N16: =SUMIFS(FortnightlyLog!$G$6:$G$300,FortnightlyLog!$E$6:$E$300,$B16,FortnightlyLog!$D$6:$D$300,N$5) -> 0 | O16: =SUM(C16:N16) -> 1542.8
B17: Total Expenses | C17: =SUM(C6:C16) -> 4736.13 | D17: =SUM(D6:D16) -> 2352.21 | E17: =SUM(E6:E16) -> 0 | F17: =SUM(F6:F16) -> 0 | G17: =SUM(G6:G16) -> 0 | H17: =SUM(H6:H16) -> 0 | I17: =SUM(I6:I16) -> 0 | J17: =SUM(J6:J16) -> 0 | ... O17: =SUM(O6:O16) -> 7088.34
B18: Total Income | C18: =Income!C12 -> 7504 | D18: =Income!D12 -> 7647 | E18: =Income!E12 -> 7504 | F18: =Income!F12 -> 10068 | G18: =Income!G12 -> 5804 | H18: =Income!H12 -> 7504 | I18: =Income!I12 -> 7694 | J18: =Income!J12 -> 7574 | ... N18: =Income!N12 -> 0 | O18: =SUM(C18:N18) -> 65086
B19: Net Savings | C19: =C18-C17 -> 2767.87 | D19: =D18-D17 -> 5294.79 | E19: =E18-E17 -> 7504 | F19: =F18-F17 -> 10068 | G19: =G18-G17 -> 5804 | H19: =H18-H17 -> 7504 | I19: =I18-I17 -> 7694 | J19: =J18-J17 -> 7574 | ... O19: =O18-O17 -> 57997.66
B20: Savings Rate | C20: =IFERROR(C19/C18,0) -> 0.36885261 | D20: =IFERROR(D19/D18,0) -> 0.69240094 | E20: =IFERROR(E19/E18,0) -> 1 | F20: =IFERROR(F19/F18,0) -> 1 | G20: =IFERROR(G19/G18,0) -> 1 | H20: =IFERROR(H19/H18,0) -> 1 | I20: =IFERROR(I19/I18,0) -> 1 | J20: =IFERROR(J19/J18,0) -> 1 | ... O20: =IFERROR(O19/O18,0) -> 0.89109271

Sheet Dashboard
B2: Budget Dashboard
B3: Live snapshot — pulls automatically from MonthlySummary. Nothing to edit here.
B5: Annual Income | D5: Annual Expenses | F5: Annual Net Savings | H5: Avg. Savings Rate
B6: =SUM(MonthlySummary!C18:N18) -> 65086 | D6: =SUM(MonthlySummary!C17:N17) -> 7088.34 | F6: =SUM(MonthlySummary!C19:N19) -> 57997.66 | H6: =IFERROR(AVERAGE(MonthlySummary!C20:N20),0) -> 0.67177113
